Workbook

Sheet summary
A1: Taxonomy 4.0: Summary
A3: Attribute Name | B3: Attribute Title | C3: Reference | D3: AtomsGroup Title
A4: material | B4: Material of the Lateral Load-Resisting System | C4: material sheet | D4: =material!B4 -> Material type
D5: =material!B24 -> Concrete technology
D6: =material!B28 -> Steel technology
D7: =material!B31 -> Metal technology
D8: =material!B33 -> Masonry technology
D9: =material!B37 -> Masonry unit type
D10: Earth technology
D11: =material!B48 -> Wood technology
D12: =material!B54 -> Mortar type
D13: =material!B59 -> Stone type
D14: =material!B66 -> Masonry reinforcement type
D15: =material!B71 -> Steel connection type
A16: llrs | B16: Lateral Load-Resisting System | C16: llrs sheet | D16: =llrs!B4 -> Type of lateral load-resisting system
D17: =llrs!B16 -> System ductility
D18: =llrs!B21 -> Columns-Wall density
A19: eq_design | B19: Earthquake design | C19: eq design sheet | D19: =eq_design!B4 -> Seismic code level
D20: =eq_design!B8 -> Earthquake resistance
D21: =eq_design!B13 -> Lateral load coefficient
D22: =eq_design!B14 -> Peak Ground Acceleration
D23: =eq_design!B16 -> Contents provisions
D24: =eq_design!B18 -> Non structural components
A25: year | B25: Wind design | C25: wind_design sheet | D25: =wind_design!B4 -> Wind resistance
D26: =wind_design!B9 -> Windows protection
A27: flood_design | B27: Flood design | C27: flood_design sheet | D27: =flood_design!B4 -> Flood resistance
D28: =flood_design!B9 -> Ground floor hydrodynamics
A29: others_design | B29: Other hazards design | C29: others_design sheet | D29: =others_design!B4 -> Fire protection
A30: height | B30: height | C30: height sheet | D30: =height!B4 -> Number of storeys
D31: =height!B6 -> height of structure (m)
D32: =height!B8 -> Number of storeys below ground
D33: =height!B11 -> height of ground floor above grade
D34: =height!B13 -> Slope of the ground (degrees)
A35: year | B35: Date of Construction or Retrofit | C35: year sheet | D35: =year!B4 -> Year of construction or retrofit
D36: =year!B6 -> Physical condition / maintenance
A37: shape | B37: Shape of the Building Plan | C37: shape sheet | D37: =shape!B4 -> Plan shape (footprint)
D38: =shape!B24 -> Building Position within a Block
A39: irregularity | B39: Structural Irregularity | C39: irregularity sheet | D39: =irregularity!B4 -> Regular or irregular
D40: =irregularity!B6 -> Irregularity
A41: ext_walls | B41: Exterior Walls | C41: ext_walls sheet | D41: =ext_walls!B4 -> Material of exterior walls
...

Sheet material
A1: material: material of the Lateral Load-Resisting System
A3: AtomsGroup Name | B3: AtomsGroup Title | C3: Atom Name | D3: Atom Title | E3: Atom Description | F3: Dependencies | G3: Example | H3: Prog | I3: Type | J3: Arguments | K3: Parameters
A4: material_type | B4: Material type | C4: C | D4: Concrete, unknown reinforcement | H4: 0
C5: CU | D5: Concrete, unreinforced | H5: =H4+100 -> 100
C6: CR | D6: Concrete, reinforced | H6: =H5+100 -> 200
C7: SRC | D7: Concrete, composite with steel section | H7: =H6+100 -> 300
C8: S | D8: Steel | H8: =H7+100 -> 400
C9: ME | D9: Metal (except steel) | H9: =H8+100 -> 500
C10: M | D10: Masonry, unknown reinforcement | H10: =H9+100 -> 600
C11: MUR | D11: Masonry, unreinforced | H11: =H10+100 -> 700
C12: MCF | D12: Masonry, confined | H12: =H11+100 -> 800
C13: MR | D13: Masonry, reinforced | H13: =H12+100 -> 900
C14: E | D14: Earth, unknown reinforcement | H14: =H13+100 -> 1000
C15: EU | D15: Earth, unreinforced | H15: =H14+100 -> 1100
C16: ER | D16: Earth, reinforced | H16: =H15+100 -> 1200
C17: W | D17: Wood | H17: =H16+100 -> 1300
C18: HYB | D18: Hybrid or composite (mixed) materials | H18: =H17+100 -> 1400 | J18: {"type": "filtered_attribute('material', ['MDD','MDV','HYB'])", "args_min": 2, "must_be_diff": true }
C19: INF | D19: Informal materials | H19: =H18+100 -> 1500
C20: MDD | D20: MDD(sys_a;sys_b), different materials in the two directions (a= system parallel to the building facade; b= system perpendicular to the building facade) | G20: MDD(CR;W) | H20: =H19+100 -> 1600 | J20: {"type": "filtered_attribute('material', ['MDD'])", "args_min": 2, "args_max": 2, "must_be_diff": true }
C21: MDV | D21: LHV(sys_a;sys_b[;...]), different materials in height (a=primary system; b=secondary system [;...]) | G21: MDV(CR;W) | H21: =H20+100 -> 1700 | J21: {"type": "filtered_attribute('material', ['MDV'])", "args_min": 2, "must_be_diff": true }
C22: MOB | D22: Mobile (manufactured) structure | H22: =H21+100 -> 1800
C23: MATO | D23: Other material | H23: =H22+100 -> 1900
A24: concrete_technology | B24: Concrete technology | C24: CIP | D24: Cast-in-place concrete | F24: CU,CR,SRC | H24: 0
C25: PC | D25: Precast concrete | F25: CU,CR,SRC | H25: =H24+100 -> 100
C26: CIPPS | D26: Cast-in-place prestressed concrete | F26: CR,SRC | H26: =H25+100 -> 200
C27: PCPS | D27: Precast prestressed concrete | F27: CR,SRC | H27: =H26+100 -> 300
A28: steel_technology | B28: Steel technology | C28: SL | D28: Cold-formed steel members | F28: S | H28: 0
C29: SR | D29: Hot-rolled steel members | F29: S | H29: =H28+100 -> 100
C30: SO | D30: Steel, other | F30: S | H30: =H29+100 -> 200
A31: metal_technology | B31: Metal technology | C31: MEIR | D31: Iron | F31: ME | H31: 0
C32: MEO | D32: Metal, other | F32: ME | H32: =H31+100 -> 100
A33: masonry_technology | B33: Masonry technology | C33: ADO | D33: Adobe blocks | F33: M,MUR,MCF,MR | H33: 0
C34: ST | D34: Stone, unknown technology | F34: M,MUR,MCF,MR | H34: =H33+100 -> 100
C35: STRUB | D35: Rubble (field stone) or semi-dressed stone | F35: M,MUR,MCF,MR | H35: =H34+100 -> 200
C36: STDRE | D36: Dressed stone | F36: M,MUR,MCF,MR | H36: =H35+100 -> 300
A37: masonry_unit_type | B37: Masonry unit type | C37: CL | D37: Fired clay unit, unknown type | F37: M,MUR,MCF,MR,-masonry_technology | H37: 0
C38: CLBRS | D38: Fired clay solid bricks | F38: M,MUR,MCF,MR,-masonry_technology | H38: =H37+100 -> 100
C39: CLBRH | D39: Fired clay hollow bricks | F39: M,MUR,MCF,MR,-masonry_technology | H39: =H38+100 -> 200
C40: CLBLH | D40: Fired clay hollow blocks or tiles | F40: M,MUR,MCF,MR,-masonry_technology | H40: =H39+100 -> 300
C41: CB | D41: Concrete blocks, unknown type | F41: M,MUR,MCF,MR,-masonry_technology | H41: =H40+100 -> 400
...

Sheet llrs
A1: llrs: Lateral Load-Resisting System
A3: AtomsGroup Name | B3: AtomsGroup Title | C3: Atom Name | D3: Atom Title | E3: Atom Description | F3: Dependencies | G3: Example | H3: Prog | I3: Type | J3: Arguments | K3: Parameters
A4: type_lateral_load | B4: Type of lateral load-resisting system | C4: LN | D4: No lateral load-resisting system | H4: 0
C5: LFM | D5: Moment frame | H5: =H4+100 -> 100
C6: LFINF | D6: Infilled frame | H6: =H5+100 -> 200 | J6: {"type": "filtered_attribute('material', ['MDD','MDV','HYB'])", "args_min": 0, "args_max": 1 }
C7: LFBR | D7: Braced frame | H7: =H6+100 -> 300
C8: LPB | D8: Post and beam | H8: =H7+100 -> 400
C9: LWAL | D9: Wall | H9: =H8+100 -> 500
C10: LDUAL | D10: Dual frame-wall system | H10: =H9+100 -> 600
C11: LFLS | D11: Flat slab/plate or waffle slab | H11: =H10+100 -> 700
C12: LFLSINF | D12: Infilled flat slab/plate or infilled waffle slab | H12: =H11+100 -> 800
C13: LDD | D13: LDD(sys_a;sys_b), different types of LLRS in the two directions (a= system parallel to the building facade; b= system perpendicular to the building facade) | G13: LDD(LFM;LWAL) | H13: =H12+100 -> 900 | J13: {"type": "filtered_attribute('llrs', ['LDD', 'LHV'])", "args_min": 2, "args_max": 2, "must_be_diff": true }
C14: LHV | D14: LHV(sys_a;sys_b), differnet LLRS in height (a=primary system, and b=secondary system) | G14: LDV(LWAL;LDUAL) | H14: =H13+100 -> 1000 | J14: {"type": "filtered_attribute('llrs', ['LDD', 'LHV'])", "args_min": 2, "must_be_diff": true }
C15: LO | D15: Other lateral load-resisting system | H15: =H14+100 -> 1100
A16: system_ductility | B16: System ductility | C16: DNO | D16: Non-ductile | H16: 0
C17: DUL | D17: Low ductility | H17: =H16+100 -> 100
C18: DUM | D18: Moderate ductility | H18: =H17+100 -> 200
C19: DUH | D19: High Ductility | H19: =H18+100 -> 300
C20: DBD | D20: Equipped with base isolation and/or energy dissipation devices | H20: =H19+100 -> 400
A21: columns_wall_density | B21: Columns-Wall density | C21: DCW | D21: Columns-Wall density | E21: Float specifying the density or ratio between the area of columns and/or walls and the area of the building plan. (DCW <= 1) | F21: LFM,LFINF,LFBR,LPB,LWAL,LDUAL,LFLS,LFLSINF | H21: 0 | K21: {"type": "float", "min": 0, "min_incl": true, "max": 1, "max_incl": true, "params_min": 1, "params_max": 1, "unit_measure": ["ratio", "ratio"] }

Sheet eq_design
A1: eq_design: Earthquake Design
A3: AtomsGroup Name | B3: AtomsGroup Title | C3: Atom Name | D3: Atom Title | E3: Atom Description | F3: Dependencies | G3: Example | H3: Prog | I3: Type | J3: Arguments | K3: Parameters
A4: seismic_code_level | B4: Seismic code level | C4: CDN | D4: No-code | H4: 0
C5: CDL | D5: Low code | H5: =H4+100 -> 100
C6: CDM | D6: Moderate code | H6: =H5+100 -> 200
C7: CDH | D7: High code | H7: =H6+100 -> 300
A8: earthquake_resistance | B8: Earthquake resistance | C8: ERN | D8: No earthquake resistance | H8: 0
C9: ERL | D9: Low earthquake resistance | H9: =H8+100 -> 100
C10: ERM | D10: Moderate earthquake resistance | H10: =H9+100 -> 200
C11: ERH | D11: High earthquake resistance | H11: =H10+100 -> 300
C12: ERS | D12: Special earthquake resistance | H12: =H11+100 -> 400
A13: lateral_load_coefficient | B13: Lateral load coefficient | C13: LFC | D13: Lateral load coefficient for earthquakes | E13: LFC:n, n is the lateral force coefficient in percentage (%) | H13: 0 | K13: {"type": "float", "min": 0.0, "min_incl": true, "max": 100.0, "max_incl": true, "params_min": 1, "params_max": 1, "unit_measure": ["%", "%"] }
A14: pga | B14: Peak Ground Acceleration | C14: PGAR | D14: Design Peak Ground Acceleration on rock conditions | E14: Units as a fraction of the gravity force PGAR:n, exact PGAR value. PGAR:a-b, range of PGAR value PGAR:<n, n upper limit of PGAR (with PGAR n excluded). PGAR:>n, n lower limit of PGAR (with PGAR n excluded). | H14: 0 | K14: { "type": "rangeable_float", "min": 0, "min_incl": true, "params_min": 1, "params_max": 1, "unit_measure": ["g", "g"] }
C15: PGAS | D15: Design Peak Ground Acceleration on soil conditions | E15: Units as a fraction of the gravity force PGAS:n, exact PGAS value. PGAS:a-b, range of PGAS value PGAS:<n, n upper limit of PGAS (with PGAS n excluded). PGAS:>n, n lower limit of PGAS (with PGAS n excluded). | H15: =H14+100 -> 100 | K15: { "type": "rangeable_float", "min": 0, "min_incl": true, "params_min": 1, "params_max": 1, "unit_measure": ["g", "g"] }
A16: contents_provisions | B16: Contents provisions | C16: CNP | D16: Contents with seismic provisions | H16: 0
C17: CNN | D17: Contents without seismic provisions | H17: =H16+100 -> 100
A18: non_strct_comp | B18: Non structural components | C18: NSP | D18: Non structural components requirements, presence | H18: 0
C19: NSN | D19: Non structural components requirements, non presence | H19: =H18+100 -> 100

Sheet wind_design
A1: wind_design: Wind Design
A3: AtomsGroup Name | B3: AtomsGroup Title | C3: Atom Name | D3: Atom Title | E3: Atom Description | F3: Dependencies | G3: Example | H3: Prog | I3: Type | J3: Arguments | K3: Parameters
A4: wind_resistance | B4: Wind resistance | C4: WRN | D4: No wind resistance | H4: 0
C5: WRL | D5: Low wind resistance | H5: =H4+100 -> 100
C6: WRM | D6: Moderate wind resistance | H6: =H5+100 -> 200
C7: WRH | D7: High wind resistance | H7: =H6+100 -> 300
C8: WRS | D8: Special wind resistance | H8: =H7+100 -> 400
A9: windows_protection | B9: Windows protection | C9: PRO | D9: Protected windows | H9: 0
C10: PNO | D10: Non protected windows | H10: =H9+100 -> 100

Sheet flood_design
A1: flood_design: Flood Design
A3: AtomsGroup Name | B3: AtomsGroup Title | C3: Atom Name | D3: Atom Title | E3: Atom Description | F3: Dependencies | G3: Example | H3: Prog | I3: Type | J3: Arguments | K3: Parameters
A4: flood_resistance | B4: Flood resistance | C4: FRN | D4: No flood resistance | H4: 0
C5: FRL | D5: Low flood resistance | H5: =H4+100 -> 100
C6: FRM | D6: Moderate flood resistance | H6: =H5+100 -> 200
C7: FRH | D7: High flood resistance | H7: =H6+100 -> 300
C8: FRS | D8: Special flood resistance | H8: =H7+100 -> 400
A9: ground_floor_hydrodynamics | B9: Ground floor hydrodynamics | C9: GFO | D9: Ground floor plan fully open (no walls) | H9: 0
C10: GFH | D10: Ground floor plan partially open (i.e. with at least 50% of walls). | H10: =H9+100 -> 100
C11: GFN | D11: Not open | H11: =H10+100 -> 200
A12: drainage | B12: Drainage requirements | C12: DRP | D12: Drainage requirements, presence | H12: 0
C13: DRN | D13: Drainage requirements, non presence | H13: =H12+100 -> 100

Sheet others_design
A1: hydrodynamics: Ground floor hydrodynamics
A3: AtomsGroup Name | B3: AtomsGroup Title | C3: Atom Name | D3: Atom Title | E3: Atom Description | F3: Dependencies | G3: Example | H3: Prog | I3: Type | J3: Arguments | K3: Parameters
A4: fire_protection | B4: Fire protection | C4: FIP | D4: Fire protection, presence | H4: 0
C5: FIN | D5: Fire protection, non presence | H5: =H4+100 -> 100

Sheet height
A1: height: height
A3: AtomsGroup Name | B3: AtomsGroup Title | C3: Atom Name | D3: Atom Title | E3: Atom Description | F3: Dependencies | G3: Example | H3: Prog | I3: Type | J3: Arguments | K3: Parameters
A4: number_of_storeys | B4: Number of storeys | C4: H | D4: Number of storeys above ground | E4: H:n, exact number of storeys above ground. H:a-b, range of storeys above ground. H:<n, n upper limit of number of storeys above ground (with n excluded). H:>n, n lower limit of number of storeys above ground (with n excluded). | H4: 0 | K4: { "type": "rangeable_int", "min": 0, "min_incl": true, "params_min": 1, "params_max": 1, "unit_measure": ["storey", "storeys"] }
C5: HAPP | D5: Approximate number of storeys above ground | E5: HAPP:n | H5: =H4+100 -> 100 | K5: { "type": "int", "min": 0, "min_incl": true, "params_min": 1, "params_max": 1, "unit_measure": ["storey", "storeys"] }
A6: height_structure_m | B6: height of structure (m) | C6: HHT | D6: Total height of the structure, measured from the ground floor. | E6: Total height of the structure, measured from the ground floor. Float specifying the height of the structures in meters. (HHT>= 1) HHT:n | H6: 0 | K6: { "type": "float", "min": 1, "min_incl": true, "params_min": 1, "params_max": 1, "unit_measure": ["meter", "meters"] }
C7: HHI | D7: Inter-storey height (average) | E7: Total height of the structure, measured from the ground floor. | H7: =H6+100 -> 100 | K7: { "type": "float", "min": 1, "min_incl": true, "params_min": 1, "params_max": 1, "unit_measure": ["meter", "meters"] }
A8: number_storeys_below | B8: Number of storeys below ground | C8: HB | D8: Number of storeys below ground | E8: Number of storeys below ground (same as number of basements). HB:n, exact number of storeys below ground. HB:a-b, range of storeys below ground. HB:<n, n upper limit of number of storeys below ground (witH n excluded). HB:>n, n lower limit of number of storeys below ground (witH n excluded). | H8: 0 | K8: { "type": "rangeable_int", "min": 0, "min_incl": true, "params_min": 1, "params_max": 1, "unit_measure": ["storey", "storeys"] }
C9: HBAPP | D9: Approximate number of storeys below ground | E9: HBAPP:n | H9: =H8+100 -> 100 | K9: { "type": "int", "min": 0, "min_incl": true, "params_min": 1, "params_max": 1, "unit_measure": ["storey", "storeys"] }
C10: HBS | D10: Basement presence. Unknown number of storeys below ground | H10: =H9+100 -> 200
A11: height_ground_floor | B11: height of ground floor above grade | C11: HF | D11: Height of ground floor level above grade | E11: HF:n, exact height of ground floor above grade. HF:a-b, range of height of ground floor above grade. HF:<n, n upper limit of the height of ground floor above grade. (with n excluded). HF:>n, n lower limit of the height of ground floor above grade. (with n excluded). | H11: 0 | K11: { "type": "rangeable_float", "min": 0, "min_incl": true, "params_min": 1, "params_max": 1, "unit_measure": ["meter", "meters"] }
C12: HFAPP | D12: Approximate height of ground floor level above grade | E12: HFAPP:n | H12: =H11+100 -> 100 | K12: { "type": "float", "min": 0, "min_incl": true, "params_min": 1, "params_max": 1, "unit_measure": ["meter", "meters"] }
A13: slope_the_ground | B13: Slope of the ground (degrees) | C13: HD | D13: Slope of the ground | E13: Slope of the ground (n=float in degrees). HD:n | H13: 0 | K13: { "type": "float", "min": 0, "min_incl": true, "max": 90, "max_incl": false, "params_min": 1, "params_max": 1, "unit_measure": ["degree", "degrees"] }

Sheet year
A1: year: Date of Construction or Retrofit
A3: AtomsGroup Name | B3: AtomsGroup Title | C3: Atom Name | D3: Atom Title | E3: Atom Description | F3: Dependencies | G3: Example | H3: Prog | I3: Type | J3: Arguments | K3: Parameters
A4: year | B4: Year of construction or retrofit | C4: Y | D4: Year of construction or retrofit | E4: Y:n, exact year of construction or retrofit. Y:a-b, range of years of construction or retrofit. Y:<n, n upper limit of year of construction or retrofit (with n excluded). Y:>n, n lower limit of year of construction or retrofit (with n excluded). | H4: 0 | K4: { "type": "rangeable_int", "params_min": 1, "params_max": 1, "unit_measure": ["year", "years"] }
C5: YAPP | D5: Approximate year of construction or retrofit | H5: =H4+100 -> 100 | K5: { "type": "int", "params_min": 1, "params_max": 1, "unit_measure": ["year", "years"] }
A6: physical_condition_maintenance | B6: Physical condition / maintenance | C6: YMP | D6: Poor physical condition/maintenance | H6: 0
C7: YMM | D7: Moderate physical condition/maintenance | H7: =H6+100 -> 100
C8: YMG | D8: Good physical condition/maintenance | H8: =H7+100 -> 200

Sheet shape
A1: shape: Shape of the Building Plan
A3: AtomsGroup Name | B3: AtomsGroup Title | C3: Atom Name | D3: Atom Title | E3: Atom Description | F3: Dependencies | G3: Example | H3: Prog | I3: Type | J3: Arguments | K3: Parameters
A4: plan_shape_footprint | B4: Plan shape (footprint) | C4: PLFSQ | D4: Square, solid | H4: 0
C5: PLFSQO | D5: Square, with an interior opening (e.g. a "donut") | H5: =H4+100 -> 100
C6: PLFR | D6: Rectangular, solid | H6: =H5+100 -> 200
C7: PLFRO | D7: Rectangular, with an opening | H7: =H6+100 -> 300
C8: PLFL | D8: L-shape | H8: =H7+100 -> 400
C9: PLFA | D9: A-shape | H9: =H8+100 -> 500
C10: PLFB | D10: B-shape | H10: =H9+100 -> 600
C11: PLFC | D11: Curved, solid (e.g. circular, elliptical, ovoid) | H11: =H10+100 -> 700
C12: PLFCO | D12: Circular, with an opening | H12: =H11+100 -> 800
C13: PLFD | D13: Triangular shape, solid | H13: =H12+100 -> 900
C14: PLFDO | D14: Triangular shape, with an opening | H14: =H13+100 -> 1000
C15: PLFE | D15: E-shape | H15: =H14+100 -> 1100
C16: PLFF | D16: F-shape | H16: =H15+100 -> 1200
... C23: PLFI | D23: Irregular plan shape | H23: =H22+100 -> 1900
A24: building_position_within | B24: Building Position within a Block | C24: BPD | D24: Detached building | H24: 0
C25: BP1 | D25: Adjoining building(s) on one side | H25: =H24+100 -> 100
C26: BP2 | D26: Adjoining buildings on two sides | H26: =H25+100 -> 200
C27: BP3 | D27: Adjoining buildings on three sides | H27: =H26+100 -> 300

Sheet irregularity
A1: irregularity: Structural Irregularity
A3: AtomsGroup Name | B3: AtomsGroup Title | C3: Atom Name | D3: Atom Title | E3: Atom Description | F3: Dependencies | G3: Example | H3: Prog | I3: Type | J3: Arguments | K3: Parameters
A4: regular_or_irregular | B4: Regular or irregular | C4: IRR | D4: Regular structure | H4: 0
C5: IRI | D5: Irregular structure | H5: =H4+100 -> 100 | J5: {"type": "filtered_atomsgroup('irregularity', [])", "args_min": 1, "must_be_diff": true }
A6: irregularity | B6: Irregularity | C6: TOR | D6: Torsion eccentricity | F6: _ARG | H6: 0
C7: REC | D7: Re-entrant corner | F7: _ARG | H7: =H6+100 -> 100
C8: IRHO | D8: Other horizontal irregularity | F8: _ARG | H8: =H7+100 -> 200
C9: SOS | D9: Soft story | F9: _ARG | H9: =H8+100 -> 300
C10: CRW | D10: Cripple wall | F10: _ARG | H10: =H9+100 -> 400
C11: SHC | D11: Short column | F11: _ARG | H11: =H10+100 -> 500
C12: POP | D12: Pounding potential | F12: _ARG | H12: =H11+100 -> 600
C13: SET | D13: Setback | F13: _ARG | H13: =H12+100 -> 700
C14: CHV | D14: Change in vertical structure (includes large overhangs) | F14: _ARG | H14: =H13+100 -> 800
C15: IRVO | D15: Other vertical irregularity | F15: _ARG | H15: =H14+100 -> 900

Sheet ext_walls
A1: ext_walls: Exterior Walls
A3: AtomsGroup Name | B3: AtomsGroup Title | C3: Atom Name | D3: Atom Title | E3: Atom Description | F3: Dependencies | G3: Example | H3: Prog | I3: Type | J3: Arguments | K3: Parameters
A4: material_exterior_walls | B4: Material of exterior walls | C4: EWC | D4: Concrete | H4: 0
C5: EWG | D5: Glass | H5: =H4+100 -> 100
C6: EWE | D6: Earth | H6: =H5+100 -> 200
C7: EWMA | D7: Masonry | H7: =H6+100 -> 300
C8: EWME | D8: Metal | H8: =H7+100 -> 400
C9: EWV | D9: Vegetative | H9: =H8+100 -> 500
C10: EWW | D10: Wood | H10: =H9+100 -> 600
C11: EWSL | D11: Stucco finish on light framing | H11: =H10+100 -> 700
C12: EWPL | D12: Plastic/vinyl, various | H12: =H11+100 -> 800
C13: EWCB | D13: Cement-based boards | H13: =H12+100 -> 900
C14: EWO | D14: Material of exterior wall, other | H14: =H13+100 -> 1000
A15: openings | B15: Openings | C15: WOL | D15: Large openings (i.e. more than 50% of the wall surface area is occupied by windows and/or doors) | H15: 0
C16: WOM | D16: Moderate openings (i.e. from 20% to 50% of the wall surface area is occupied by windows and/or doors) | H16: =H15+100 -> 100
C17: WOS | D17: Small openings (i.e. less than 20% of the wall surface area is occupied by windows and/or doors) | H17: =H16+100 -> 200
C18: WON | D18: No openings | H18: =H17+100 -> 300

Sheet roof
A1: roof: Roof
A3: AtomsGroup Name | B3: AtomsGroup Title | C3: Atom Name | D3: Atom Title | E3: Atom Description | F3: Dependencies | G3: Example | H3: Prog | I3: Type | J3: Arguments | K3: Parameters
A4: roof_shape | B4: Roof shape | C4: RSH1 | D4: Flat | H4: 0
C5: RSH2 | D5: Pitched with gable ends | H5: =H4+100 -> 100
C6: RSH3 | D6: Pitched and hipped | H6: =H5+100 -> 200
C7: RSH4 | D7: Pitched with dormers | H7: =H6+100 -> 300
C8: RSH5 | D8: Monopitch | H8: =H7+100 -> 400
C9: RSH6 | D9: Sawtooth | H9: =H8+100 -> 500
C10: RSH7 | D10: Curved | H10: =H9+100 -> 600
C11: RSH8 | D11: Complex regular | H11: =H10+100 -> 700
C12: RSH9 | D12: Complex irregular | H12: =H11+100 -> 800
C13: RSHO | D13: Roof shape, other | H13: =H12+100 -> 900
A14: roof_covering_material | B14: Roof covering material | C14: RMN | D14: Concrete roof without additional covering | H14: 0
C15: RMT1 | D15: Clay or concrete tile | H15: =H14+100 -> 100
C16: RMT2 | D16: Fibre cement or metal tile | H16: =H15+100 -> 200
C17: RMT3 | D17: Membrane roofing | H17: =H16+100 -> 300
C18: RMT4 | D18: Slate | H18: =H17+100 -> 400
C19: RMT5 | D19: Stone slab | H19: =H18+100 -> 500
C20: RMT6 | D20: Metal or asbestos sheets | H20: =H19+100 -> 600
C21: RMT7 | D21: Wooden and asphalt shingles | H21: =H20+100 -> 700
C22: RMT8 | D22: Vegetative | H22: =H21+100 -> 800
C23: RMT9 | D23: Earthen | H23: =H22+100 -> 900
C24: RMT10 | D24: Solar panelled roofs | H24: =H23+100 -> 1000
C25: RMT11 | D25: Tensile membrane or fabric roof | H25: =H24+100 -> 1100
C26: RMTO | D26: Roof covering, other | H26: =H25+100 -> 1200
A27: roof_type | B27: Roof type | C27: RM | D27: Masonry | H27: 0 | K27: {"type": "options", "params_min": 0, "params_max": 1}
C28: RM:1 | D28: Vaulted masonry | H28: =H27+100 -> 100
C29: RM:2 | D29: Shallow-arched masonry | H29: =H28+100 -> 200
C30: RM:3 | D30: Composite masonry and concrete roof system | H30: =H29+100 -> 300
C31: RE | D31: Earthen | H31: =H30+100 -> 400 | K31: {"type": "options", "params_min": 0, "params_max": 1}
C32: RE:1 | D32: Vaulted earthen roof | H32: =H31+100 -> 500
C33: RC | D33: Concrete | H33: =H32+100 -> 600 | K33: {"type": "options", "params_min": 0, "params_max": 1}
C34: RC:1 | D34: Cast-in-place beamless reinforced concrete roof | H34: =H33+100 -> 700
C35: RC:2 | D35: Cast-in-place beam-supported reinforced concrete roof | H35: =H34+100 -> 800
C36: RC:3 | D36: Precast concrete roof with reinforced concrete topping | H36: =H35+100 -> 900
C37: RC:4 | D37: Precast concrete roof without reinforced concrete topping | H37: =H36+100 -> 1000
C38: RME | D38: Metal or steel | H38: =H37+100 -> 1100 | K38: {"type": "options", "params_min": 0, "params_max": 1}
C39: RME:1 | D39: Metal or steel beams or trusses supporting light roofing | H39: =H38+100 -> 1200
C40: RME:2 | D40: Metal or steel beams supporting precast concrete slabs | H40: =H39+100 -> 1300
C41: RME:3 | D41: Composite steel deck and concrete slab | H41: =H40+100 -> 1400
...

Sheet floor
A1: floor: Floor
A3: AtomsGroup Name | B3: AtomsGroup Title | C3: Atom Name | D3: Atom Title | E3: Atom Description | F3: Dependencies | G3: Example | H3: Prog | I3: Type | J3: Arguments | K3: Parameters
A4: floor_system_material | B4: Floor system material | C4: FN | D4: No elevated or suspended floor material (single-storey building) | H4: 0
C5: FM | D5: Masonry | H5: =H4+100 -> 100 | K5: {"type": "options", "params_min": 0, "params_max": 1}
C6: FM:1 | D6: Vaulted masonry | H6: =H5+100 -> 200
C7: FM:2 | D7: Shallow-arched masonry | H7: =H6+100 -> 300
C8: FM:3 | D8: Composite cast-in-place reinforced concrete and masonry floor system | H8: =H7+100 -> 400
C9: FE | D9: Earthen | H9: =H8+100 -> 500
C10: FC | D10: Concrete | H10: =H9+100 -> 600 | K10: {"type": "options", "params_min": 0, "params_max": 1}
C11: FC:1 | D11: Cast-in-place beamless reinforced concrete floor | H11: =H10+100 -> 700
C12: FC:2 | D12: Cast-in-place beam-supported reinforced concrete floor | H12: =H11+100 -> 800
C13: FC:3 | D13: Precast concrete floor with reinforced concrete topping | H13: =H12+100 -> 900
C14: FC:4 | D14: Precast concrete floor without reinforced concrete topping | H14: =H13+100 -> 1000
C15: FME | D15: Metal | H15: =H14+100 -> 1100 | K15: {"type": "options", "params_min": 0, "params_max": 1}
C16: FME:1 | D16: Metal beams, trusses, or joists supporting light flooring | H16: =H15+100 -> 1200
C17: FME:2 | D17: Metal beams supporting precast concrete slabs | H17: =H16+100 -> 1300
C18: FME:3 | D18: Composite steel deck and concrete slab | H18: =H17+100 -> 1400
C19: FW | D19: Wood | H19: =H18+100 -> 1500 | K19: {"type": "options", "params_min": 0, "params_max": 1}
C20: FW:1 | D20: Wooden beams or trusses and joists supporting light flooring | H20: =H19+100 -> 1600
C21: FW:2 | D21: Wooden beams or trusses and joists supporting heavy flooring | H21: =H20+100 -> 1700
C22: FW:3 | D22: Wood-based sheets on joists or beams | H22: =H21+100 -> 1800
C23: FW:4 | D23: Plywood panels or other light-weight panels for floor | H23: =H22+100 -> 1900
C24: FO | D24: Floor material, other | H24: =H23+100 -> 2000
A25: floor_connections | B25: Floor connections | C25: FWCN | D25: Floor-wall diaphragm connection not provided | H25: 0
C26: FWCP | D26: Floor-wall diaphragm connection present (the role of the connection is to restrain wall out-of-plane forces and to transfer in-plane forces to wall) | H26: =H25+100 -> 100

Sheet foundation
A1: foundation: Foundation System
A3: AtomsGroup Name | B3: AtomsGroup Title | C3: Atom Name | D3: Atom Title | E3: Atom Description | F3: Dependencies | G3: Example | H3: Prog | I3: Type | J3: Arguments | K3: Parameters
A4: foundation_system | B4: Foundation System | C4: FOSSL | D4: Shallow foundation, with lateral capacity | H4: 0
C5: FOSN | D5: Shallow foundation, no lateral capacity | H5: =H4+100 -> 100
C6: FOSDL | D6: Deep foundation, with lateral capacity | H6: =H5+100 -> 200
C7: FOSDN | D7: Deep foundation, no lateral capacity | H7: =H6+100 -> 300
C8: FOSO | D8: Foundation, other | H8: =H7+100 -> 400

Sheet occupancy
A1: occupancy: Occupancy
A3: AtomsGroup Name | B3: AtomsGroup Title | C3: Atom Name | D3: Atom Title | E3: Atom Description | F3: Dependencies | G3: Example | H3: Prog | I3: Type | J3: Arguments | K3: Parameters
A4: building_occupancy_class | B4: Building occupancy class | C4: RES | D4: Residential | H4: 0 | K4: {"type": "options", "params_min": 0, "params_max": 1}
C5: RES:1 | D5: Single dwelling | H5: =H4+100 -> 100
C6: RES:2 | D6: Multi-unit, unknown type | H6: =H5+100 -> 200
C7: RES:2A | D7: 2 Units (duplex) | H7: =H6+100 -> 300
C8: RES:2B | D8: 3-4 Units | H8: =H7+100 -> 400
C9: RES:2C | D9: 5-9 Units | H9: =H8+100 -> 500
C10: RES:2D | D10: 10-19 Units | H10: =H9+100 -> 600
C11: RES:2E | D11: 20-49 Units | H11: =H10+100 -> 700
C12: RES:2F | D12: 50+ Units | H12: =H11+100 -> 800
C13: RES:4 | D13: Institutional housing | H13: =H12+100 -> 900
C14: RES:6 | D14: Indigenous housing | H14: =H13+100 -> 1000
C15: NONRES | D15: Not residential | H15: =H14+100 -> 1100
C16: COM | D16: Commercial and public | H16: =H15+100 -> 1200 | K16: {"type": "options", "params_min": 0, "params_max": 1}
C17: COM:1 | D17: Retail trade | H17: =H16+100 -> 1300
C18: COM:2 | D18: Wholesale trade and storage (warehouse) | H18: =H17+100 -> 1400
C19: COM:3 | D19: Offices, professional/technical services | H19: =H18+100 -> 1500
C20: COM:3A | D20: Financial and insurance activities | H20: =H19+100 -> 1600
C21: COM:3B | D21: Personal and Repair Services | H21: =H20+100 -> 1700
C22: COM:3C | D22: Hotels and motels | H22: =H21+100 -> 1800
C23: COM:4 | D23: Covered parking garage | H23: =H22+100 -> 1900
C24: COM:5 | D24: Entertainment and recreation | H24: =H23+100 -> 2000
C25: COM:5A | D25: Entertainment | H25: =H24+100 -> 2100
C26: COM:5B | D26: Recreation | H26: =H25+100 -> 2200
C27: COM:5C | D27: Religious gathering | H27: =H26+100 -> 2300
C28: COM:5D | D28: Arena | H28: =H27+100 -> 2400
C29: COM:5E | D29: Cinema, auditoriums or concert hall | H29: =H28+100 -> 2500
C30: MIX | D30: Mixed occupancy types | E30: MIX(RES;COM) | H30: =H29+100 -> 2600 | J30: {"type": "filtered_atomsgroup('building_occupancy_class', ['MIX'])", "args_min": 2, "must_be_diff": true }
C31: IND | D31: Industrial | H31: =H30+100 -> 2700 | K31: {"type": "options", "params_min": 0, "params_max": 1}
C32: IND:1 | D32: Heavy Industry Factories | H32: =H31+100 -> 2800
C33: IND:2 | D33: Light Industry Factories | H33: =H32+100 -> 2900
C34: IND:3 | D34: Food/Drugs/Chemicals Factories | H34: =H33+100 -> 3000
C35: IND:4 | D35: Metals/Minerals Processing Factories | H35: =H34+100 -> 3100
C36: IND:5 | D36: High technology Labs/Factories | H36: =H35+100 -> 3200
C37: IND:6 | D37: Construction Offices | H37: =H36+100 -> 3300
C38: AGR | D38: Agriculture | H38: =H37+100 -> 3400 | K38: {"type": "options", "params_min": 0, "params_max": 1}
C39: AGR:1 | D39: Produce storage | H39: =H38+100 -> 3500
C40: AGR:2 | D40: Animal shelter | H40: =H39+100 -> 3600
C41: AGR:3 | D41: Agricultural processing | H41: =H40+100 -> 3700
...
